2021-04-22 10:05:00,972 (88369/MainThread) pgcli.main INFO - No default pager found in environment. Using os default pager
2021-04-22 10:05:00,973 (88369/MainThread) pgcli.main WARNING - import keyring failed: ModuleNotFoundError("No module named 'keyring'").
2021-04-22 10:05:00,977 (88369/MainThread) pgcli.main ERROR - traceback: 'Traceback (most recent call last):\n  File "/usr/local/Cellar/pgcli/3.1.0/libexec/lib/python3.9/site-packages/pgcli/main.py", line 582, in connect\n    raise e\n  File "/usr/local/Cellar/pgcli/3.1.0/libexec/lib/python3.9/site-packages/pgcli/main.py", line 569, in connect\n    pgexecute = PGExecute(database, user, passwd, host, port, dsn, **kwargs)\n  File "/usr/local/Cellar/pgcli/3.1.0/libexec/lib/python3.9/site-packages/pgcli/pgexecute.py", line 214, in __init__\n    self.connect(database, user, password, host, port, dsn, **kwargs)\n  File "/usr/local/Cellar/pgcli/3.1.0/libexec/lib/python3.9/site-packages/pgcli/pgexecute.py", line 254, in connect\n    conn = psycopg2.connect(**conn_params)\n  File "/usr/local/Cellar/pgcli/3.1.0/libexec/lib/python3.9/site-packages/psycopg2/__init__.py", line 127, in connect\n    conn = _connect(dsn, connection_factory=connection_factory, **kwasync)\npsycopg2.OperationalError: could not connect to server: No such file or directory\n\tIs the server running locally and accepting\n\tconnections on Unix domain socket "/tmp/.s.PGSQL.5432"?\n\n'
2021-04-22 10:05:55,804 (88436/MainThread) pgcli.main INFO - No default pager found in environment. Using os default pager
2021-04-22 10:05:55,804 (88436/MainThread) pgcli.main WARNING - import keyring failed: ModuleNotFoundError("No module named 'keyring'").
2021-04-22 10:06:58,273 (88495/MainThread) pgcli.main INFO - No default pager found in environment. Using os default pager
2021-04-22 10:06:58,273 (88495/MainThread) pgcli.main WARNING - import keyring failed: ModuleNotFoundError("No module named 'keyring'").
2021-04-22 10:07:03,616 (88495/MainThread) pgcli.main ERROR - traceback: 'Traceback (most recent call last):\n  File "/usr/local/Cellar/pgcli/3.1.0/libexec/lib/python3.9/site-packages/pgcli/main.py", line 569, in connect\n    pgexecute = PGExecute(database, user, passwd, host, port, dsn, **kwargs)\n  File "/usr/local/Cellar/pgcli/3.1.0/libexec/lib/python3.9/site-packages/pgcli/pgexecute.py", line 214, in __init__\n    self.connect(database, user, password, host, port, dsn, **kwargs)\n  File "/usr/local/Cellar/pgcli/3.1.0/libexec/lib/python3.9/site-packages/pgcli/pgexecute.py", line 254, in connect\n    conn = psycopg2.connect(**conn_params)\n  File "/usr/local/Cellar/pgcli/3.1.0/libexec/lib/python3.9/site-packages/psycopg2/__init__.py", line 127, in connect\n    conn = _connect(dsn, connection_factory=connection_factory, **kwasync)\n  File "/usr/local/Cellar/pgcli/3.1.0/libexec/lib/python3.9/site-packages/pgcli/pgexecute.py", line 39, in _wait_select\n    state = conn.poll()\npsycopg2.OperationalError: fe_sendauth: no password supplied\n\n\nDuring handling of the above exception, another exception occurred:\n\nTraceback (most recent call last):\n  File "/usr/local/Cellar/pgcli/3.1.0/libexec/lib/python3.9/site-packages/click/termui.py", line 129, in prompt_func\n    return f("")\n  File "/usr/local/Cellar/pgcli/3.1.0/libexec/lib/python3.9/site-packages/click/termui.py", line 54, in hidden_prompt_func\n    return getpass.getpass(prompt)\n  File "/usr/local/Cellar/python@3.9/3.9.4/Frameworks/Python.framework/Versions/3.9/lib/python3.9/getpass.py", line 77, in unix_getpass\n    passwd = _raw_input(prompt, stream, input=input)\n  File "/usr/local/Cellar/python@3.9/3.9.4/Frameworks/Python.framework/Versions/3.9/lib/python3.9/getpass.py", line 146, in _raw_input\n    line = input.readline()\nKeyboardInterrupt\n\nDuring handling of the above exception, another exception occurred:\n\nTraceback (most recent call last):\n  File "/usr/local/Cellar/pgcli/3.1.0/libexec/lib/python3.9/site-packages/pgcli/main.py", line 572, in connect\n    passwd = click.prompt(\n  File "/usr/local/Cellar/pgcli/3.1.0/libexec/lib/python3.9/site-packages/click/termui.py", line 147, in prompt\n    value = prompt_func(prompt)\n  File "/usr/local/Cellar/pgcli/3.1.0/libexec/lib/python3.9/site-packages/click/termui.py", line 136, in prompt_func\n    raise Abort()\nclick.exceptions.Abort\n'
2021-04-22 10:07:55,088 (88535/MainThread) pgcli.main INFO - No default pager found in environment. Using os default pager
2021-04-22 10:07:55,089 (88535/MainThread) pgcli.main WARNING - import keyring failed: ModuleNotFoundError("No module named 'keyring'").
2021-04-22 10:07:57,767 (88535/MainThread) pgcli.main ERROR - traceback: 'Traceback (most recent call last):\n  File "/usr/local/Cellar/pgcli/3.1.0/libexec/lib/python3.9/site-packages/pgcli/main.py", line 569, in connect\n    pgexecute = PGExecute(database, user, passwd, host, port, dsn, **kwargs)\n  File "/usr/local/Cellar/pgcli/3.1.0/libexec/lib/python3.9/site-packages/pgcli/pgexecute.py", line 214, in __init__\n    self.connect(database, user, password, host, port, dsn, **kwargs)\n  File "/usr/local/Cellar/pgcli/3.1.0/libexec/lib/python3.9/site-packages/pgcli/pgexecute.py", line 254, in connect\n    conn = psycopg2.connect(**conn_params)\n  File "/usr/local/Cellar/pgcli/3.1.0/libexec/lib/python3.9/site-packages/psycopg2/__init__.py", line 127, in connect\n    conn = _connect(dsn, connection_factory=connection_factory, **kwasync)\n  File "/usr/local/Cellar/pgcli/3.1.0/libexec/lib/python3.9/site-packages/pgcli/pgexecute.py", line 39, in _wait_select\n    state = conn.poll()\npsycopg2.OperationalError: fe_sendauth: no password supplied\n\n\nDuring handling of the above exception, another exception occurred:\n\nTraceback (most recent call last):\n  File "/usr/local/Cellar/pgcli/3.1.0/libexec/lib/python3.9/site-packages/click/termui.py", line 129, in prompt_func\n    return f("")\n  File "/usr/local/Cellar/pgcli/3.1.0/libexec/lib/python3.9/site-packages/click/termui.py", line 54, in hidden_prompt_func\n    return getpass.getpass(prompt)\n  File "/usr/local/Cellar/python@3.9/3.9.4/Frameworks/Python.framework/Versions/3.9/lib/python3.9/getpass.py", line 77, in unix_getpass\n    passwd = _raw_input(prompt, stream, input=input)\n  File "/usr/local/Cellar/python@3.9/3.9.4/Frameworks/Python.framework/Versions/3.9/lib/python3.9/getpass.py", line 146, in _raw_input\n    line = input.readline()\nKeyboardInterrupt\n\nDuring handling of the above exception, another exception occurred:\n\nTraceback (most recent call last):\n  File "/usr/local/Cellar/pgcli/3.1.0/libexec/lib/python3.9/site-packages/pgcli/main.py", line 572, in connect\n    passwd = click.prompt(\n  File "/usr/local/Cellar/pgcli/3.1.0/libexec/lib/python3.9/site-packages/click/termui.py", line 147, in prompt\n    value = prompt_func(prompt)\n  File "/usr/local/Cellar/pgcli/3.1.0/libexec/lib/python3.9/site-packages/click/termui.py", line 136, in prompt_func\n    raise Abort()\nclick.exceptions.Abort\n'
2021-04-22 10:08:23,697 (88593/MainThread) pgcli.main INFO - No default pager found in environment. Using os default pager
2021-04-22 10:08:23,698 (88593/MainThread) pgcli.main WARNING - import keyring failed: ModuleNotFoundError("No module named 'keyring'").
2021-04-22 10:18:52,072 (89539/MainThread) pgcli.main INFO - No default pager found in environment. Using os default pager
2021-04-22 10:18:52,072 (89539/MainThread) pgcli.main WARNING - import keyring failed: ModuleNotFoundError("No module named 'keyring'").
2021-04-22 10:37:58,042 (89539/MainThread) pgcli.pgexecute ERROR - sql: '\\exit', error: SyntaxError('syntax error at or near "\\"\nLINE 1: \\exit\n        ^\n')
2021-04-22 10:37:58,044 (89539/MainThread) pgcli.pgexecute ERROR - traceback: 'Traceback (most recent call last):\n  File "/usr/local/Cellar/pgcli/3.1.0/libexec/lib/python3.9/site-packages/pgcli/pgexecute.py", line 409, in run\n    yield self.execute_normal_sql(sql) + (sql, True, False)\n  File "/usr/local/Cellar/pgcli/3.1.0/libexec/lib/python3.9/site-packages/pgcli/pgexecute.py", line 444, in execute_normal_sql\n    cur.execute(split_sql)\npsycopg2.errors.SyntaxError: syntax error at or near "\\"\nLINE 1: \\exit\n        ^\n\n'
2021-04-22 10:40:52,014 (90330/MainThread) pgcli.main INFO - No default pager found in environment. Using os default pager
2021-04-22 10:40:52,014 (90330/MainThread) pgcli.main WARNING - import keyring failed: ModuleNotFoundError("No module named 'keyring'").
2021-04-22 10:41:10,195 (90330/MainThread) pgcli.main ERROR - traceback: 'Traceback (most recent call last):\n  File "/usr/local/Cellar/pgcli/3.1.0/libexec/lib/python3.9/site-packages/pgcli/main.py", line 569, in connect\n    pgexecute = PGExecute(database, user, passwd, host, port, dsn, **kwargs)\n  File "/usr/local/Cellar/pgcli/3.1.0/libexec/lib/python3.9/site-packages/pgcli/pgexecute.py", line 214, in __init__\n    self.connect(database, user, password, host, port, dsn, **kwargs)\n  File "/usr/local/Cellar/pgcli/3.1.0/libexec/lib/python3.9/site-packages/pgcli/pgexecute.py", line 254, in connect\n    conn = psycopg2.connect(**conn_params)\n  File "/usr/local/Cellar/pgcli/3.1.0/libexec/lib/python3.9/site-packages/psycopg2/__init__.py", line 127, in connect\n    conn = _connect(dsn, connection_factory=connection_factory, **kwasync)\n  File "/usr/local/Cellar/pgcli/3.1.0/libexec/lib/python3.9/site-packages/pgcli/pgexecute.py", line 39, in _wait_select\n    state = conn.poll()\npsycopg2.OperationalError: fe_sendauth: no password supplied\n\n\nDuring handling of the above exception, another exception occurred:\n\nTraceback (most recent call last):\n  File "/usr/local/Cellar/pgcli/3.1.0/libexec/lib/python3.9/site-packages/click/termui.py", line 129, in prompt_func\n    return f("")\n  File "/usr/local/Cellar/pgcli/3.1.0/libexec/lib/python3.9/site-packages/click/termui.py", line 54, in hidden_prompt_func\n    return getpass.getpass(prompt)\n  File "/usr/local/Cellar/python@3.9/3.9.4/Frameworks/Python.framework/Versions/3.9/lib/python3.9/getpass.py", line 77, in unix_getpass\n    passwd = _raw_input(prompt, stream, input=input)\n  File "/usr/local/Cellar/python@3.9/3.9.4/Frameworks/Python.framework/Versions/3.9/lib/python3.9/getpass.py", line 146, in _raw_input\n    line = input.readline()\nKeyboardInterrupt\n\nDuring handling of the above exception, another exception occurred:\n\nTraceback (most recent call last):\n  File "/usr/local/Cellar/pgcli/3.1.0/libexec/lib/python3.9/site-packages/pgcli/main.py", line 572, in connect\n    passwd = click.prompt(\n  File "/usr/local/Cellar/pgcli/3.1.0/libexec/lib/python3.9/site-packages/click/termui.py", line 147, in prompt\n    value = prompt_func(prompt)\n  File "/usr/local/Cellar/pgcli/3.1.0/libexec/lib/python3.9/site-packages/click/termui.py", line 136, in prompt_func\n    raise Abort()\nclick.exceptions.Abort\n'
2021-04-22 10:41:41,420 (90410/MainThread) pgcli.main INFO - No default pager found in environment. Using os default pager
2021-04-22 10:41:41,421 (90410/MainThread) pgcli.main WARNING - import keyring failed: ModuleNotFoundError("No module named 'keyring'").
2021-05-06 14:02:01,316 (43160/MainThread) pgcli.main INFO - No default pager found in environment. Using os default pager
2021-05-06 14:02:01,317 (43160/MainThread) pgcli.main WARNING - import keyring failed: ModuleNotFoundError("No module named 'keyring'").
2022-03-09 10:15:01,937 (91539/MainThread) pgcli.main INFO - No default pager found in environment. Using os default pager
2022-03-09 10:15:01,938 (91539/MainThread) pgcli.main WARNING - import keyring failed: ModuleNotFoundError("No module named 'keyring'").
2022-03-09 10:15:01,944 (91539/MainThread) pgcli.main ERROR - traceback: 'Traceback (most recent call last):\n  File "/usr/local/Cellar/pgcli/3.3.1/libexec/lib/python3.9/site-packages/pgcli/main.py", line 607, in connect\n    raise e\n  File "/usr/local/Cellar/pgcli/3.3.1/libexec/lib/python3.9/site-packages/pgcli/main.py", line 594, in connect\n    pgexecute = PGExecute(database, user, passwd, host, port, dsn, **kwargs)\n  File "/usr/local/Cellar/pgcli/3.3.1/libexec/lib/python3.9/site-packages/pgcli/pgexecute.py", line 260, in __init__\n    self.connect(database, user, password, host, port, dsn, **kwargs)\n  File "/usr/local/Cellar/pgcli/3.3.1/libexec/lib/python3.9/site-packages/pgcli/pgexecute.py", line 306, in connect\n    conn = psycopg2.connect(**conn_params)\n  File "/usr/local/Cellar/pgcli/3.3.1/libexec/lib/python3.9/site-packages/psycopg2/__init__.py", line 122, in connect\n    conn = _connect(dsn, connection_factory=connection_factory, **kwasync)\npsycopg2.OperationalError: connection to server on socket "/tmp/.s.PGSQL.5432" failed: No such file or directory\n\tIs the server running locally and accepting connections on that socket?\n\n'
2022-03-09 10:15:05,461 (91562/MainThread) pgcli.main INFO - No default pager found in environment. Using os default pager
2022-03-09 10:15:05,461 (91562/MainThread) pgcli.main WARNING - import keyring failed: ModuleNotFoundError("No module named 'keyring'").
2022-03-09 10:15:05,465 (91562/MainThread) pgcli.main ERROR - traceback: 'Traceback (most recent call last):\n  File "/usr/local/Cellar/pgcli/3.3.1/libexec/lib/python3.9/site-packages/pgcli/main.py", line 607, in connect\n    raise e\n  File "/usr/local/Cellar/pgcli/3.3.1/libexec/lib/python3.9/site-packages/pgcli/main.py", line 594, in connect\n    pgexecute = PGExecute(database, user, passwd, host, port, dsn, **kwargs)\n  File "/usr/local/Cellar/pgcli/3.3.1/libexec/lib/python3.9/site-packages/pgcli/pgexecute.py", line 260, in __init__\n    self.connect(database, user, password, host, port, dsn, **kwargs)\n  File "/usr/local/Cellar/pgcli/3.3.1/libexec/lib/python3.9/site-packages/pgcli/pgexecute.py", line 306, in connect\n    conn = psycopg2.connect(**conn_params)\n  File "/usr/local/Cellar/pgcli/3.3.1/libexec/lib/python3.9/site-packages/psycopg2/__init__.py", line 122, in connect\n    conn = _connect(dsn, connection_factory=connection_factory, **kwasync)\npsycopg2.OperationalError: connection to server on socket "/tmp/.s.PGSQL.5432" failed: No such file or directory\n\tIs the server running locally and accepting connections on that socket?\n\n'
2022-03-09 10:15:40,972 (91625/MainThread) pgcli.main INFO - No default pager found in environment. Using os default pager
2022-03-09 10:15:40,973 (91625/MainThread) pgcli.main WARNING - import keyring failed: ModuleNotFoundError("No module named 'keyring'").
2022-03-09 10:15:41,002 (91625/MainThread) pgcli.main ERROR - traceback: 'Traceback (most recent call last):\n  File "/usr/local/Cellar/pgcli/3.3.1/libexec/lib/python3.9/site-packages/pgcli/main.py", line 607, in connect\n    raise e\n  File "/usr/local/Cellar/pgcli/3.3.1/libexec/lib/python3.9/site-packages/pgcli/main.py", line 594, in connect\n    pgexecute = PGExecute(database, user, passwd, host, port, dsn, **kwargs)\n  File "/usr/local/Cellar/pgcli/3.3.1/libexec/lib/python3.9/site-packages/pgcli/pgexecute.py", line 260, in __init__\n    self.connect(database, user, password, host, port, dsn, **kwargs)\n  File "/usr/local/Cellar/pgcli/3.3.1/libexec/lib/python3.9/site-packages/pgcli/pgexecute.py", line 306, in connect\n    conn = psycopg2.connect(**conn_params)\n  File "/usr/local/Cellar/pgcli/3.3.1/libexec/lib/python3.9/site-packages/psycopg2/__init__.py", line 122, in connect\n    conn = _connect(dsn, connection_factory=connection_factory, **kwasync)\npsycopg2.OperationalError: connection to server at "localhost" (::1), port 51560 failed: FATAL:  role "schambers" does not exist\n\n'
2022-03-09 10:22:36,407 (347/MainThread) pgcli.main INFO - No default pager found in environment. Using os default pager
2022-03-09 10:22:36,408 (347/MainThread) pgcli.main WARNING - import keyring failed: ModuleNotFoundError("No module named 'keyring'").
2022-03-09 10:29:43,394 (347/MainThread) pgcli.pgexecute ERROR - sql: "select to_json(*) from wsm.scanners where scanner_id = '7f849925-c871-4faa-bee9-892fc6c06d6a'", error: UndefinedFunction("function to_json() does not exist\nLINE 1: select to_json(*) from wsm.scanners where scanner_id = '7f84...\n               ^\nHINT:  No function matches the given name and argument types. You might need to add explicit type casts.\n")
2022-03-09 10:29:43,396 (347/MainThread) pgcli.pgexecute ERROR - traceback: 'Traceback (most recent call last):\n  File "/usr/local/Cellar/pgcli/3.3.1/libexec/lib/python3.9/site-packages/pgcli/pgexecute.py", line 472, in run\n    yield self.execute_normal_sql(sql) + (sql, True, False)\n  File "/usr/local/Cellar/pgcli/3.3.1/libexec/lib/python3.9/site-packages/pgcli/pgexecute.py", line 507, in execute_normal_sql\n    cur.execute(split_sql)\n  File "/usr/local/Cellar/pgcli/3.3.1/libexec/lib/python3.9/site-packages/pgcli/pgexecute.py", line 168, in execute\n    psycopg2.extensions.cursor.execute(self, sql, args)\npsycopg2.errors.UndefinedFunction: function to_json() does not exist\nLINE 1: select to_json(*) from wsm.scanners where scanner_id = \'7f84...\n               ^\nHINT:  No function matches the given name and argument types. You might need to add explicit type casts.\n\n'
2022-03-09 12:06:39,080 (347/MainThread) pgcli.pgexecute ERROR - sql: "update wsm.scans SET scanner = row_to_jsonb(scanner) FROM (select * from wsm.scanners where scanner_id = '7f849925-c871-4faa-bee9-892fc6c06d6a') as scanner where scan_id = 'da39df9a-e9fa-4489-8a43-b1e373a55b78'", error: UndefinedFunction('function row_to_jsonb(jsonb) does not exist\nLINE 1: update wsm.scans SET scanner = row_to_jsonb(scanner) FROM (s...\n                                       ^\nHINT:  No function matches the given name and argument types. You might need to add explicit type casts.\n')
2022-03-09 12:06:39,082 (347/MainThread) pgcli.pgexecute ERROR - traceback: 'Traceback (most recent call last):\n  File "/usr/local/Cellar/pgcli/3.3.1/libexec/lib/python3.9/site-packages/pgcli/pgexecute.py", line 472, in run\n    yield self.execute_normal_sql(sql) + (sql, True, False)\n  File "/usr/local/Cellar/pgcli/3.3.1/libexec/lib/python3.9/site-packages/pgcli/pgexecute.py", line 507, in execute_normal_sql\n    cur.execute(split_sql)\n  File "/usr/local/Cellar/pgcli/3.3.1/libexec/lib/python3.9/site-packages/pgcli/pgexecute.py", line 168, in execute\n    psycopg2.extensions.cursor.execute(self, sql, args)\npsycopg2.errors.UndefinedFunction: function row_to_jsonb(jsonb) does not exist\nLINE 1: update wsm.scans SET scanner = row_to_jsonb(scanner) FROM (s...\n                                       ^\nHINT:  No function matches the given name and argument types. You might need to add explicit type casts.\n\n'
2022-03-09 12:07:38,693 (347/MainThread) pgcli.pgexecute ERROR - sql: "update wsm.scans SET scanner = row_to_jsonb(scanner) FROM (select * from wsm.scanners where scanner_id = '7f849925-c871-4faa-bee9-892fc6c06d6a') scanner where scan_id = 'da39df9a-e9fa-4489-8a43-b1e373a55b78'", error: UndefinedFunction('function row_to_jsonb(jsonb) does not exist\nLINE 1: update wsm.scans SET scanner = row_to_jsonb(scanner) FROM (s...\n                                       ^\nHINT:  No function matches the given name and argument types. You might need to add explicit type casts.\n')
2022-03-09 12:07:38,693 (347/MainThread) pgcli.pgexecute ERROR - traceback: 'Traceback (most recent call last):\n  File "/usr/local/Cellar/pgcli/3.3.1/libexec/lib/python3.9/site-packages/pgcli/pgexecute.py", line 472, in run\n    yield self.execute_normal_sql(sql) + (sql, True, False)\n  File "/usr/local/Cellar/pgcli/3.3.1/libexec/lib/python3.9/site-packages/pgcli/pgexecute.py", line 507, in execute_normal_sql\n    cur.execute(split_sql)\n  File "/usr/local/Cellar/pgcli/3.3.1/libexec/lib/python3.9/site-packages/pgcli/pgexecute.py", line 168, in execute\n    psycopg2.extensions.cursor.execute(self, sql, args)\npsycopg2.errors.UndefinedFunction: function row_to_jsonb(jsonb) does not exist\nLINE 1: update wsm.scans SET scanner = row_to_jsonb(scanner) FROM (s...\n                                       ^\nHINT:  No function matches the given name and argument types. You might need to add explicit type casts.\n\n'
2022-03-09 12:11:06,820 (347/MainThread) pgcli.pgexecute ERROR - sql: "update wsm.scans SET scanner = scanner_json FROM (SELECT to_json(scanner) from  (select * from wsm.scanners where scanner_id = '7f849925-c871-4faa-bee9-892fc6c06d6a') scanner) scanner_json where scan_id = 'da39df9a-e9fa-4489-8a43-b1e373a55b78'", error: DatatypeMismatch('column "scanner" is of type jsonb but expression is of type record\nLINE 1: update wsm.scans SET scanner = scanner_json FROM (SELECT to_...\n                                       ^\nHINT:  You will need to rewrite or cast the expression.\n')
2022-03-09 12:11:06,820 (347/MainThread) pgcli.pgexecute ERROR - traceback: 'Traceback (most recent call last):\n  File "/usr/local/Cellar/pgcli/3.3.1/libexec/lib/python3.9/site-packages/pgcli/pgexecute.py", line 472, in run\n    yield self.execute_normal_sql(sql) + (sql, True, False)\n  File "/usr/local/Cellar/pgcli/3.3.1/libexec/lib/python3.9/site-packages/pgcli/pgexecute.py", line 507, in execute_normal_sql\n    cur.execute(split_sql)\n  File "/usr/local/Cellar/pgcli/3.3.1/libexec/lib/python3.9/site-packages/pgcli/pgexecute.py", line 168, in execute\n    psycopg2.extensions.cursor.execute(self, sql, args)\npsycopg2.errors.DatatypeMismatch: column "scanner" is of type jsonb but expression is of type record\nLINE 1: update wsm.scans SET scanner = scanner_json FROM (SELECT to_...\n                                       ^\nHINT:  You will need to rewrite or cast the expression.\n\n'
